** ComfyUI start up time: 2023-12-11 20:38:15.400701

Prestartup times for custom nodes:
   0.0 seconds: C:\Users\don00\projects\ComfyUI\custom_nodes\ComfyUI-Manager

Total VRAM 6144 MB, total RAM 16292 MB
Set vram state to: NORMAL_VRAM
Device: cuda:0 NVIDIA GeForce RTX 2060 : cudaMallocAsync
VAE dtype: torch.float32
Using pytorch cross attention
========= possible_module base64_images.py =========
========= possible_module comfyui-animatediff =========
Traceback (most recent call last):
  File "C:\Users\don00\projects\ComfyUI\nodes.py", line 1800, in load_custom_node
    module_spec.loader.exec_module(module)
  File "<frozen importlib._bootstrap_external>", line 940, in exec_module
  File "<frozen importlib._bootstrap>", line 241, in _call_with_frames_removed
  File "C:\Users\don00\projects\ComfyUI\custom_nodes\comfyui-animatediff\__init__.py", line 2, in <module>
    from .animatediff.nodes import NODE_CLASS_MAPPINGS, NODE_DISPLAY_NAME_MAPPINGS
  File "C:\Users\don00\projects\ComfyUI\custom_nodes\comfyui-animatediff\animatediff\nodes.py", line 16, in <module>
    from .sampler import AnimateDiffSampler, AnimateDiffSlidingWindowOptions
  File "C:\Users\don00\projects\ComfyUI\custom_nodes\comfyui-animatediff\animatediff\sampler.py", line 52, in <module>
    orig_maximum_batch_area = model_management.maximum_batch_area
                              ^^^^^^^^^^^^^^^^^^^^^^^^^^^^^^^^^^^
AttributeError: module 'comfy.model_management' has no attribute 'maximum_batch_area'

Cannot import C:\Users\don00\projects\ComfyUI\custom_nodes\comfyui-animatediff module for custom nodes: module 'comfy.model_management' has no attribute 'maximum_batch_area'
========= possible_module ComfyUI-AnimateDiff-Evolved =========
Using pytorch cross attention
Traceback (most recent call last):
  File "C:\Users\don00\projects\ComfyUI\nodes.py", line 1800, in load_custom_node
    module_spec.loader.exec_module(module)
  File "<frozen importlib._bootstrap_external>", line 940, in exec_module
  File "<frozen importlib._bootstrap>", line 241, in _call_with_frames_removed
  File "C:\Users\don00\projects\ComfyUI\custom_nodes\ComfyUI-AnimateDiff-Evolved\__init__.py", line 2, in <module>
    from .animatediff.nodes import NODE_CLASS_MAPPINGS, NODE_DISPLAY_NAME_MAPPINGS
  File "C:\Users\don00\projects\ComfyUI\custom_nodes\ComfyUI-AnimateDiff-Evolved\animatediff\nodes.py", line 22, in <module>
    from .sampling import animatediff_sample_factory
  File "C:\Users\don00\projects\ComfyUI\custom_nodes\ComfyUI-AnimateDiff-Evolved\animatediff\sampling.py", line 9, in <module>
    from comfy.samplers import lcm
ImportError: cannot import name 'lcm' from 'comfy.samplers' (C:\Users\don00\projects\ComfyUI\comfy\samplers.py)

Cannot import C:\Users\don00\projects\ComfyUI\custom_nodes\ComfyUI-AnimateDiff-Evolved module for custom nodes: cannot import name 'lcm' from 'comfy.samplers' (C:\Users\don00\projects\ComfyUI\comfy\samplers.py)
========= possible_module ComfyUI-Manager =========
### Loading: ComfyUI-Manager (V0.36)
### ComfyUI Revision: 1777 [e1d95343] | Released on '2023-12-07'
========= possible_module ComfyUI-VideoHelperSuite =========
Traceback (most recent call last):
  File "C:\Users\don00\projects\ComfyUI\nodes.py", line 1800, in load_custom_node
    module_spec.loader.exec_module(module)
  File "<frozen importlib._bootstrap_external>", line 940, in exec_module
  File "<frozen importlib._bootstrap>", line 241, in _call_with_frames_removed
  File "C:\Users\don00\projects\ComfyUI\custom_nodes\ComfyUI-VideoHelperSuite\__init__.py", line 1, in <module>
    from .videohelpersuite.nodes import NODE_CLASS_MAPPINGS, NODE_DISPLAY_NAME_MAPPINGS
  File "C:\Users\don00\projects\ComfyUI\custom_nodes\ComfyUI-VideoHelperSuite\videohelpersuite\nodes.py", line 13, in <module>
    from .load_video_nodes import LoadVideo, LoadVideoUpload, UploadVideo, OutVideoInfo
  File "C:\Users\don00\projects\ComfyUI\custom_nodes\ComfyUI-VideoHelperSuite\videohelpersuite\load_video_nodes.py", line 6, in <module>
    import cv2
ModuleNotFoundError: No module named 'cv2'

Cannot import C:\Users\don00\projects\ComfyUI\custom_nodes\ComfyUI-VideoHelperSuite module for custom nodes: No module named 'cv2'
========= possible_module efficiency-nodes-comfyui =========
[36mEfficiency Nodes:[0m Attempting to add 'AnimatedDiff Script' Node (ComfyUI-AnimateDiff-Evolved add-on)...[36mEfficiency Nodes:[0m Attempting to add 'AnimatedDiff Script' Node (ComfyUI-AnimateDiff-Evolved add-on)...[91mFailed![0m
[93mEfficiency Nodes Warning:[0m Failed to import python package 'simpleeval'; related nodes disabled.

========= possible_module example_node.py.example =========

Import times for custom nodes:
   0.0 seconds: C:\Users\don00\projects\ComfyUI\custom_nodes\base64_images.py
   0.1 seconds: C:\Users\don00\projects\ComfyUI\custom_nodes\efficiency-nodes-comfyui
   0.1 seconds (IMPORT FAILED): C:\Users\don00\projects\ComfyUI\custom_nodes\ComfyUI-VideoHelperSuite
   0.1 seconds (IMPORT FAILED): C:\Users\don00\projects\ComfyUI\custom_nodes\comfyui-animatediff
   0.1 seconds (IMPORT FAILED): C:\Users\don00\projects\ComfyUI\custom_nodes\ComfyUI-AnimateDiff-Evolved
   0.9 seconds: C:\Users\don00\projects\ComfyUI\custom_nodes\ComfyUI-Manager

Starting server

To see the GUI go to: http://127.0.0.1:8188
got prompt
ERROR:root:!!! Exception during processing !!!
ERROR:root:Traceback (most recent call last):
  File "C:\Users\don00\projects\ComfyUI\execution.py", line 155, in recursive_execute
    output_data, output_ui = get_output_data(obj, input_data_all)
                             ^^^^^^^^^^^^^^^^^^^^^^^^^^^^^^^^^^^^
  File "C:\Users\don00\projects\ComfyUI\execution.py", line 85, in get_output_data
    return_values = map_node_over_list(obj, input_data_all, obj.FUNCTION, allow_interrupt=True)
                    ^^^^^^^^^^^^^^^^^^^^^^^^^^^^^^^^^^^^^^^^^^^^^^^^^^^^^^^^^^^^^^^^^^^^^^^^^^^
  File "C:\Users\don00\projects\ComfyUI\execution.py", line 78, in map_node_over_list
    results.append(getattr(obj, func)(**slice_dict(input_data_all, i)))
                   ^^^^^^^^^^^^^^^^^^^^^^^^^^^^^^^^^^^^^^^^^^^^^^^^^^^
  File "C:\Users\don00\projects\ComfyUI\custom_nodes\base64_images.py", line 97, in base64_to_image
    _bytes = base64.decodebytes(bytes(base64Str, 'utf-8'))
             ^^^^^^^^^^^^^^^^^^^^^^^^^^^^^^^^^^^^^^^^^^^^^
  File "C:\Program Files\WindowsApps\PythonSoftwareFoundation.Python.3.11_3.11.2032.0_x64__qbz5n2kfra8p0\Lib\base64.py", line 563, in decodebytes
    return binascii.a2b_base64(s)
           ^^^^^^^^^^^^^^^^^^^^^^
binascii.Error: Invalid base64-encoded string: number of data characters (353) cannot be 1 more than a multiple of 4

Prompt executed in 118.02 seconds
gc collect
got prompt
ERROR:root:!!! Exception during processing !!!
ERROR:root:Traceback (most recent call last):
  File "C:\Users\don00\projects\ComfyUI\execution.py", line 155, in recursive_execute
    output_data, output_ui = get_output_data(obj, input_data_all)
                             ^^^^^^^^^^^^^^^^^^^^^^^^^^^^^^^^^^^^
  File "C:\Users\don00\projects\ComfyUI\execution.py", line 85, in get_output_data
    return_values = map_node_over_list(obj, input_data_all, obj.FUNCTION, allow_interrupt=True)
                    ^^^^^^^^^^^^^^^^^^^^^^^^^^^^^^^^^^^^^^^^^^^^^^^^^^^^^^^^^^^^^^^^^^^^^^^^^^^
  File "C:\Users\don00\projects\ComfyUI\execution.py", line 78, in map_node_over_list
    results.append(getattr(obj, func)(**slice_dict(input_data_all, i)))
                   ^^^^^^^^^^^^^^^^^^^^^^^^^^^^^^^^^^^^^^^^^^^^^^^^^^^
  File "C:\Users\don00\projects\ComfyUI\custom_nodes\base64_images.py", line 97, in base64_to_image
    _bytes = base64.decodebytes(bytes(base64Str, 'utf-8'))
             ^^^^^^^^^^^^^^^^^^^^^^^^^^^^^^^^^^^^^^^^^^^^^
  File "C:\Program Files\WindowsApps\PythonSoftwareFoundation.Python.3.11_3.11.2032.0_x64__qbz5n2kfra8p0\Lib\base64.py", line 563, in decodebytes
    return binascii.a2b_base64(s)
           ^^^^^^^^^^^^^^^^^^^^^^
binascii.Error: Invalid base64-encoded string: number of data characters (353) cannot be 1 more than a multiple of 4

Prompt executed in 326.84 seconds
ERROR:asyncio:Task exception was never retrieved
future: <Task finished name='Task-10' coro=<RequestHandler.start() done, defined at C:\Users\don00\AppData\Local\Packages\PythonSoftwareFoundation.Python.3.11_qbz5n2kfra8p0\LocalCache\local-packages\Python311\site-packages\aiohttp\web_protocol.py:481> exception=AssertionError()>
Traceback (most recent call last):
  File "C:\Users\don00\AppData\Local\Packages\PythonSoftwareFoundation.Python.3.11_qbz5n2kfra8p0\LocalCache\local-packages\Python311\site-packages\aiohttp\web_protocol.py", line 524, in start
    request = self._request_factory(message, payload, self, writer, handler)
              ^^^^^^^^^^^^^^^^^^^^^^^^^^^^^^^^^^^^^^^^^^^^^^^^^^^^^^^^^^^^^^
  File "C:\Users\don00\AppData\Local\Packages\PythonSoftwareFoundation.Python.3.11_qbz5n2kfra8p0\LocalCache\local-packages\Python311\site-packages\aiohttp\web_app.py", line 485, in _make_request
    return _cls(
           ^^^^^
  File "C:\Users\don00\AppData\Local\Packages\PythonSoftwareFoundation.Python.3.11_qbz5n2kfra8p0\LocalCache\local-packages\Python311\site-packages\aiohttp\web_request.py", line 825, in __init__
    super().__init__(*args, **kwargs)
  File "C:\Users\don00\AppData\Local\Packages\PythonSoftwareFoundation.Python.3.11_qbz5n2kfra8p0\LocalCache\local-packages\Python311\site-packages\aiohttp\web_request.py", line 195, in __init__
    assert transport is not None
           ^^^^^^^^^^^^^^^^^^^^^
AssertionError
gc collect
got prompt
Requested to load SD1ClipModel
Loading 1 new model
----------------------------------------
[36mEfficient Loader Models Cache:[0m
Ckpt:
  [1] realisticVisionV60B1_v60B1VAE
got prompt
Prompt executed in 85.90 seconds
ERROR:asyncio:Task exception was never retrieved
future: <Task finished name='Task-14' coro=<RequestHandler.start() done, defined at C:\Users\don00\AppData\Local\Packages\PythonSoftwareFoundation.Python.3.11_qbz5n2kfra8p0\LocalCache\local-packages\Python311\site-packages\aiohttp\web_protocol.py:481> exception=AssertionError()>
Traceback (most recent call last):
  File "C:\Users\don00\AppData\Local\Packages\PythonSoftwareFoundation.Python.3.11_qbz5n2kfra8p0\LocalCache\local-packages\Python311\site-packages\aiohttp\web_protocol.py", line 524, in start
    request = self._request_factory(message, payload, self, writer, handler)
              ^^^^^^^^^^^^^^^^^^^^^^^^^^^^^^^^^^^^^^^^^^^^^^^^^^^^^^^^^^^^^^
  File "C:\Users\don00\AppData\Local\Packages\PythonSoftwareFoundation.Python.3.11_qbz5n2kfra8p0\LocalCache\local-packages\Python311\site-packages\aiohttp\web_app.py", line 485, in _make_request
    return _cls(
           ^^^^^
  File "C:\Users\don00\AppData\Local\Packages\PythonSoftwareFoundation.Python.3.11_qbz5n2kfra8p0\LocalCache\local-packages\Python311\site-packages\aiohttp\web_request.py", line 825, in __init__
    super().__init__(*args, **kwargs)
  File "C:\Users\don00\AppData\Local\Packages\PythonSoftwareFoundation.Python.3.11_qbz5n2kfra8p0\LocalCache\local-packages\Python311\site-packages\aiohttp\web_request.py", line 195, in __init__
    assert transport is not None
           ^^^^^^^^^^^^^^^^^^^^^
AssertionError
ERROR:asyncio:Task exception was never retrieved
future: <Task finished name='Task-16' coro=<RequestHandler.start() done, defined at C:\Users\don00\AppData\Local\Packages\PythonSoftwareFoundation.Python.3.11_qbz5n2kfra8p0\LocalCache\local-packages\Python311\site-packages\aiohttp\web_protocol.py:481> exception=AssertionError()>
Traceback (most recent call last):
  File "C:\Users\don00\AppData\Local\Packages\PythonSoftwareFoundation.Python.3.11_qbz5n2kfra8p0\LocalCache\local-packages\Python311\site-packages\aiohttp\web_protocol.py", line 524, in start
    request = self._request_factory(message, payload, self, writer, handler)
              ^^^^^^^^^^^^^^^^^^^^^^^^^^^^^^^^^^^^^^^^^^^^^^^^^^^^^^^^^^^^^^
  File "C:\Users\don00\AppData\Local\Packages\PythonSoftwareFoundation.Python.3.11_qbz5n2kfra8p0\LocalCache\local-packages\Python311\site-packages\aiohttp\web_app.py", line 485, in _make_request
    return _cls(
           ^^^^^
  File "C:\Users\don00\AppData\Local\Packages\PythonSoftwareFoundation.Python.3.11_qbz5n2kfra8p0\LocalCache\local-packages\Python311\site-packages\aiohttp\web_request.py", line 825, in __init__
    super().__init__(*args, **kwargs)
  File "C:\Users\don00\AppData\Local\Packages\PythonSoftwareFoundation.Python.3.11_qbz5n2kfra8p0\LocalCache\local-packages\Python311\site-packages\aiohttp\web_request.py", line 195, in __init__
    assert transport is not None
           ^^^^^^^^^^^^^^^^^^^^^
AssertionError
ERROR:asyncio:Task exception was never retrieved
future: <Task finished name='Task-20' coro=<RequestHandler.start() done, defined at C:\Users\don00\AppData\Local\Packages\PythonSoftwareFoundation.Python.3.11_qbz5n2kfra8p0\LocalCache\local-packages\Python311\site-packages\aiohttp\web_protocol.py:481> exception=AssertionError()>
Traceback (most recent call last):
  File "C:\Users\don00\AppData\Local\Packages\PythonSoftwareFoundation.Python.3.11_qbz5n2kfra8p0\LocalCache\local-packages\Python311\site-packages\aiohttp\web_protocol.py", line 524, in start
    request = self._request_factory(message, payload, self, writer, handler)
              ^^^^^^^^^^^^^^^^^^^^^^^^^^^^^^^^^^^^^^^^^^^^^^^^^^^^^^^^^^^^^^
  File "C:\Users\don00\AppData\Local\Packages\PythonSoftwareFoundation.Python.3.11_qbz5n2kfra8p0\LocalCache\local-packages\Python311\site-packages\aiohttp\web_app.py", line 485, in _make_request
    return _cls(
           ^^^^^
  File "C:\Users\don00\AppData\Local\Packages\PythonSoftwareFoundation.Python.3.11_qbz5n2kfra8p0\LocalCache\local-packages\Python311\site-packages\aiohttp\web_request.py", line 825, in __init__
    super().__init__(*args, **kwargs)
  File "C:\Users\don00\AppData\Local\Packages\PythonSoftwareFoundation.Python.3.11_qbz5n2kfra8p0\LocalCache\local-packages\Python311\site-packages\aiohttp\web_request.py", line 195, in __init__
    assert transport is not None
           ^^^^^^^^^^^^^^^^^^^^^
AssertionError
ERROR:asyncio:Task exception was never retrieved
future: <Task finished name='Task-25' coro=<RequestHandler.start() done, defined at C:\Users\don00\AppData\Local\Packages\PythonSoftwareFoundation.Python.3.11_qbz5n2kfra8p0\LocalCache\local-packages\Python311\site-packages\aiohttp\web_protocol.py:481> exception=AssertionError()>
Traceback (most recent call last):
  File "C:\Users\don00\AppData\Local\Packages\PythonSoftwareFoundation.Python.3.11_qbz5n2kfra8p0\LocalCache\local-packages\Python311\site-packages\aiohttp\web_protocol.py", line 524, in start
    request = self._request_factory(message, payload, self, writer, handler)
              ^^^^^^^^^^^^^^^^^^^^^^^^^^^^^^^^^^^^^^^^^^^^^^^^^^^^^^^^^^^^^^
  File "C:\Users\don00\AppData\Local\Packages\PythonSoftwareFoundation.Python.3.11_qbz5n2kfra8p0\LocalCache\local-packages\Python311\site-packages\aiohttp\web_app.py", line 485, in _make_request
    return _cls(
           ^^^^^
  File "C:\Users\don00\AppData\Local\Packages\PythonSoftwareFoundation.Python.3.11_qbz5n2kfra8p0\LocalCache\local-packages\Python311\site-packages\aiohttp\web_request.py", line 825, in __init__
    super().__init__(*args, **kwargs)
  File "C:\Users\don00\AppData\Local\Packages\PythonSoftwareFoundation.Python.3.11_qbz5n2kfra8p0\LocalCache\local-packages\Python311\site-packages\aiohttp\web_request.py", line 195, in __init__
    assert transport is not None
           ^^^^^^^^^^^^^^^^^^^^^
AssertionError
gc collect
ERROR:root:!!! Exception during processing !!!
ERROR:root:Traceback (most recent call last):
  File "C:\Users\don00\projects\ComfyUI\execution.py", line 155, in recursive_execute
    output_data, output_ui = get_output_data(obj, input_data_all)
                             ^^^^^^^^^^^^^^^^^^^^^^^^^^^^^^^^^^^^
  File "C:\Users\don00\projects\ComfyUI\execution.py", line 85, in get_output_data
    return_values = map_node_over_list(obj, input_data_all, obj.FUNCTION, allow_interrupt=True)
                    ^^^^^^^^^^^^^^^^^^^^^^^^^^^^^^^^^^^^^^^^^^^^^^^^^^^^^^^^^^^^^^^^^^^^^^^^^^^
  File "C:\Users\don00\projects\ComfyUI\execution.py", line 78, in map_node_over_list
    results.append(getattr(obj, func)(**slice_dict(input_data_all, i)))
                   ^^^^^^^^^^^^^^^^^^^^^^^^^^^^^^^^^^^^^^^^^^^^^^^^^^^
  File "C:\Users\don00\projects\ComfyUI\custom_nodes\base64_images.py", line 97, in base64_to_image
    _bytes = base64.decodebytes(bytes(base64Str, 'utf-8'))
             ^^^^^^^^^^^^^^^^^^^^^^^^^^^^^^^^^^^^^^^^^^^^^
  File "C:\Program Files\WindowsApps\PythonSoftwareFoundation.Python.3.11_3.11.2032.0_x64__qbz5n2kfra8p0\Lib\base64.py", line 563, in decodebytes
    return binascii.a2b_base64(s)
           ^^^^^^^^^^^^^^^^^^^^^^
binascii.Error: Incorrect padding

Prompt executed in 0.86 seconds
got prompt
ERROR:root:!!! Exception during processing !!!
ERROR:root:Traceback (most recent call last):
  File "C:\Users\don00\projects\ComfyUI\execution.py", line 155, in recursive_execute
    output_data, output_ui = get_output_data(obj, input_data_all)
                             ^^^^^^^^^^^^^^^^^^^^^^^^^^^^^^^^^^^^
  File "C:\Users\don00\projects\ComfyUI\execution.py", line 85, in get_output_data
    return_values = map_node_over_list(obj, input_data_all, obj.FUNCTION, allow_interrupt=True)
                    ^^^^^^^^^^^^^^^^^^^^^^^^^^^^^^^^^^^^^^^^^^^^^^^^^^^^^^^^^^^^^^^^^^^^^^^^^^^
  File "C:\Users\don00\projects\ComfyUI\execution.py", line 78, in map_node_over_list
    results.append(getattr(obj, func)(**slice_dict(input_data_all, i)))
                   ^^^^^^^^^^^^^^^^^^^^^^^^^^^^^^^^^^^^^^^^^^^^^^^^^^^
  File "C:\Users\don00\projects\ComfyUI\custom_nodes\base64_images.py", line 97, in base64_to_image
    _bytes = base64.decodebytes(bytes(base64Str, 'utf-8'))
             ^^^^^^^^^^^^^^^^^^^^^^^^^^^^^^^^^^^^^^^^^^^^^
  File "C:\Program Files\WindowsApps\PythonSoftwareFoundation.Python.3.11_3.11.2032.0_x64__qbz5n2kfra8p0\Lib\base64.py", line 563, in decodebytes
    return binascii.a2b_base64(s)
           ^^^^^^^^^^^^^^^^^^^^^^
binascii.Error: Incorrect padding

Prompt executed in 22.86 seconds
gc collect
got prompt
Requested to load AutoencoderKL
Loading 1 new model
100%|█████████████████████████████████████████████████████████████████████████████████████████████████████████████████████████████████████| 20/20 [00:04<00:00,  6.45it/s]100%|█████████████████████████████████████████████████████████████████████████████████████████████████████████████████████████████████████| 20/20 [00:04<00:00,  4.69it/s]
Prompt executed in 38.54 seconds
gc collect
got prompt
100%|█████████████████████████████████████████████████████████████████████████████████████████████████████████████████████████████████████| 20/20 [00:03<00:00,  7.84it/s]100%|█████████████████████████████████████████████████████████████████████████████████████████████████████████████████████████████████████| 20/20 [00:03<00:00,  6.30it/s]
Prompt executed in 24.84 seconds
gc collect
got prompt
ERROR:root:!!! Exception during processing !!!
ERROR:root:Traceback (most recent call last):
  File "C:\Users\don00\projects\ComfyUI\execution.py", line 155, in recursive_execute
    output_data, output_ui = get_output_data(obj, input_data_all)
                             ^^^^^^^^^^^^^^^^^^^^^^^^^^^^^^^^^^^^
  File "C:\Users\don00\projects\ComfyUI\execution.py", line 85, in get_output_data
    return_values = map_node_over_list(obj, input_data_all, obj.FUNCTION, allow_interrupt=True)
                    ^^^^^^^^^^^^^^^^^^^^^^^^^^^^^^^^^^^^^^^^^^^^^^^^^^^^^^^^^^^^^^^^^^^^^^^^^^^
  File "C:\Users\don00\projects\ComfyUI\execution.py", line 78, in map_node_over_list
    results.append(getattr(obj, func)(**slice_dict(input_data_all, i)))
                   ^^^^^^^^^^^^^^^^^^^^^^^^^^^^^^^^^^^^^^^^^^^^^^^^^^^
  File "C:\Users\don00\projects\ComfyUI\custom_nodes\base64_images.py", line 97, in base64_to_image
    base64Str = urllib.parse.unquote(base64Str)
             ^^^^^^^^^^^^^^^^^^^^^^^^^^^^^^^^^^^
  File "C:\Program Files\WindowsApps\PythonSoftwareFoundation.Python.3.11_3.11.2032.0_x64__qbz5n2kfra8p0\Lib\base64.py", line 563, in decodebytes
    return binascii.a2b_base64(s)
           ^^^^^^^^^^^^^^^^^^^^^^
binascii.Error: Invalid base64-encoded string: number of data characters (1) cannot be 1 more than a multiple of 4

Prompt executed in 192.65 seconds
ERROR:asyncio:Task exception was never retrieved
future: <Task finished name='Task-81' coro=<RequestHandler.start() done, defined at C:\Users\don00\AppData\Local\Packages\PythonSoftwareFoundation.Python.3.11_qbz5n2kfra8p0\LocalCache\local-packages\Python311\site-packages\aiohttp\web_protocol.py:481> exception=AssertionError()>
Traceback (most recent call last):
  File "C:\Users\don00\AppData\Local\Packages\PythonSoftwareFoundation.Python.3.11_qbz5n2kfra8p0\LocalCache\local-packages\Python311\site-packages\aiohttp\web_protocol.py", line 524, in start
    request = self._request_factory(message, payload, self, writer, handler)
              ^^^^^^^^^^^^^^^^^^^^^^^^^^^^^^^^^^^^^^^^^^^^^^^^^^^^^^^^^^^^^^
  File "C:\Users\don00\AppData\Local\Packages\PythonSoftwareFoundation.Python.3.11_qbz5n2kfra8p0\LocalCache\local-packages\Python311\site-packages\aiohttp\web_app.py", line 485, in _make_request
    return _cls(
           ^^^^^
  File "C:\Users\don00\AppData\Local\Packages\PythonSoftwareFoundation.Python.3.11_qbz5n2kfra8p0\LocalCache\local-packages\Python311\site-packages\aiohttp\web_request.py", line 825, in __init__
    super().__init__(*args, **kwargs)
  File "C:\Users\don00\AppData\Local\Packages\PythonSoftwareFoundation.Python.3.11_qbz5n2kfra8p0\LocalCache\local-packages\Python311\site-packages\aiohttp\web_request.py", line 195, in __init__
    assert transport is not None
           ^^^^^^^^^^^^^^^^^^^^^
AssertionError
ERROR:asyncio:Task exception was never retrieved
future: <Task finished name='Task-83' coro=<RequestHandler.start() done, defined at C:\Users\don00\AppData\Local\Packages\PythonSoftwareFoundation.Python.3.11_qbz5n2kfra8p0\LocalCache\local-packages\Python311\site-packages\aiohttp\web_protocol.py:481> exception=AssertionError()>
Traceback (most recent call last):
  File "C:\Users\don00\AppData\Local\Packages\PythonSoftwareFoundation.Python.3.11_qbz5n2kfra8p0\LocalCache\local-packages\Python311\site-packages\aiohttp\web_protocol.py", line 524, in start
    request = self._request_factory(message, payload, self, writer, handler)
              ^^^^^^^^^^^^^^^^^^^^^^^^^^^^^^^^^^^^^^^^^^^^^^^^^^^^^^^^^^^^^^
  File "C:\Users\don00\AppData\Local\Packages\PythonSoftwareFoundation.Python.3.11_qbz5n2kfra8p0\LocalCache\local-packages\Python311\site-packages\aiohttp\web_app.py", line 485, in _make_request
    return _cls(
           ^^^^^
  File "C:\Users\don00\AppData\Local\Packages\PythonSoftwareFoundation.Python.3.11_qbz5n2kfra8p0\LocalCache\local-packages\Python311\site-packages\aiohttp\web_request.py", line 825, in __init__
    super().__init__(*args, **kwargs)
  File "C:\Users\don00\AppData\Local\Packages\PythonSoftwareFoundation.Python.3.11_qbz5n2kfra8p0\LocalCache\local-packages\Python311\site-packages\aiohttp\web_request.py", line 195, in __init__
    assert transport is not None
           ^^^^^^^^^^^^^^^^^^^^^
AssertionError
ERROR:asyncio:Task exception was never retrieved
future: <Task finished name='Task-98' coro=<RequestHandler.start() done, defined at C:\Users\don00\AppData\Local\Packages\PythonSoftwareFoundation.Python.3.11_qbz5n2kfra8p0\LocalCache\local-packages\Python311\site-packages\aiohttp\web_protocol.py:481> exception=AssertionError()>
Traceback (most recent call last):
  File "C:\Users\don00\AppData\Local\Packages\PythonSoftwareFoundation.Python.3.11_qbz5n2kfra8p0\LocalCache\local-packages\Python311\site-packages\aiohttp\web_protocol.py", line 524, in start
    request = self._request_factory(message, payload, self, writer, handler)
              ^^^^^^^^^^^^^^^^^^^^^^^^^^^^^^^^^^^^^^^^^^^^^^^^^^^^^^^^^^^^^^
  File "C:\Users\don00\AppData\Local\Packages\PythonSoftwareFoundation.Python.3.11_qbz5n2kfra8p0\LocalCache\local-packages\Python311\site-packages\aiohttp\web_app.py", line 485, in _make_request
    return _cls(
           ^^^^^
  File "C:\Users\don00\AppData\Local\Packages\PythonSoftwareFoundation.Python.3.11_qbz5n2kfra8p0\LocalCache\local-packages\Python311\site-packages\aiohttp\web_request.py", line 825, in __init__
    super().__init__(*args, **kwargs)
  File "C:\Users\don00\AppData\Local\Packages\PythonSoftwareFoundation.Python.3.11_qbz5n2kfra8p0\LocalCache\local-packages\Python311\site-packages\aiohttp\web_request.py", line 195, in __init__
    assert transport is not None
           ^^^^^^^^^^^^^^^^^^^^^
AssertionError
gc collect
got prompt
ERROR:root:!!! Exception during processing !!!
ERROR:root:Traceback (most recent call last):
  File "C:\Users\don00\projects\ComfyUI\execution.py", line 155, in recursive_execute
    output_data, output_ui = get_output_data(obj, input_data_all)
                             ^^^^^^^^^^^^^^^^^^^^^^^^^^^^^^^^^^^^
  File "C:\Users\don00\projects\ComfyUI\execution.py", line 85, in get_output_data
    return_values = map_node_over_list(obj, input_data_all, obj.FUNCTION, allow_interrupt=True)
                    ^^^^^^^^^^^^^^^^^^^^^^^^^^^^^^^^^^^^^^^^^^^^^^^^^^^^^^^^^^^^^^^^^^^^^^^^^^^
  File "C:\Users\don00\projects\ComfyUI\execution.py", line 78, in map_node_over_list
    results.append(getattr(obj, func)(**slice_dict(input_data_all, i)))
                   ^^^^^^^^^^^^^^^^^^^^^^^^^^^^^^^^^^^^^^^^^^^^^^^^^^^
  File "C:\Users\don00\projects\ComfyUI\custom_nodes\base64_images.py", line 98, in base64_to_image
    _bytes = base64.decodebytes(bytes(base64Str, 'utf-8'))
        ^^^^^^^^^^^^^^^^^^^^^^^^^^^
  File "C:\Users\don00\AppData\Local\Packages\PythonSoftwareFoundation.Python.3.11_qbz5n2kfra8p0\LocalCache\local-packages\Python311\site-packages\PIL\Image.py", line 3305, in open
    raise UnidentifiedImageError(msg)
PIL.UnidentifiedImageError: cannot identify image file <_io.BytesIO object at 0x00000288F8AA3560>

Prompt executed in 3.64 seconds
gc collect
got prompt
ERROR:root:!!! Exception during processing !!!
ERROR:root:Traceback (most recent call last):
  File "C:\Users\don00\projects\ComfyUI\execution.py", line 155, in recursive_execute
    output_data, output_ui = get_output_data(obj, input_data_all)
                             ^^^^^^^^^^^^^^^^^^^^^^^^^^^^^^^^^^^^
  File "C:\Users\don00\projects\ComfyUI\execution.py", line 85, in get_output_data
    return_values = map_node_over_list(obj, input_data_all, obj.FUNCTION, allow_interrupt=True)
                    ^^^^^^^^^^^^^^^^^^^^^^^^^^^^^^^^^^^^^^^^^^^^^^^^^^^^^^^^^^^^^^^^^^^^^^^^^^^
  File "C:\Users\don00\projects\ComfyUI\execution.py", line 78, in map_node_over_list
    results.append(getattr(obj, func)(**slice_dict(input_data_all, i)))
                   ^^^^^^^^^^^^^^^^^^^^^^^^^^^^^^^^^^^^^^^^^^^^^^^^^^^
  File "C:\Users\don00\projects\ComfyUI\custom_nodes\base64_images.py", line 98, in base64_to_image
    _bytes = base64.decodebytes(bytes(base64StrDecoded, 'utf-8'))
        ^^^^^^^^^^^^^^^^^^^^^^^^^^^
  File "C:\Users\don00\AppData\Local\Packages\PythonSoftwareFoundation.Python.3.11_qbz5n2kfra8p0\LocalCache\local-packages\Python311\site-packages\PIL\Image.py", line 3305, in open
    raise UnidentifiedImageError(msg)
PIL.UnidentifiedImageError: cannot identify image file <_io.BytesIO object at 0x000002898536AC50>

Prompt executed in 110.84 seconds
ERROR:asyncio:Task exception was never retrieved
future: <Task finished name='Task-102' coro=<RequestHandler.start() done, defined at C:\Users\don00\AppData\Local\Packages\PythonSoftwareFoundation.Python.3.11_qbz5n2kfra8p0\LocalCache\local-packages\Python311\site-packages\aiohttp\web_protocol.py:481> exception=AssertionError()>
Traceback (most recent call last):
  File "C:\Users\don00\AppData\Local\Packages\PythonSoftwareFoundation.Python.3.11_qbz5n2kfra8p0\LocalCache\local-packages\Python311\site-packages\aiohttp\web_protocol.py", line 524, in start
    request = self._request_factory(message, payload, self, writer, handler)
              ^^^^^^^^^^^^^^^^^^^^^^^^^^^^^^^^^^^^^^^^^^^^^^^^^^^^^^^^^^^^^^
  File "C:\Users\don00\AppData\Local\Packages\PythonSoftwareFoundation.Python.3.11_qbz5n2kfra8p0\LocalCache\local-packages\Python311\site-packages\aiohttp\web_app.py", line 485, in _make_request
    return _cls(
           ^^^^^
  File "C:\Users\don00\AppData\Local\Packages\PythonSoftwareFoundation.Python.3.11_qbz5n2kfra8p0\LocalCache\local-packages\Python311\site-packages\aiohttp\web_request.py", line 825, in __init__
    super().__init__(*args, **kwargs)
  File "C:\Users\don00\AppData\Local\Packages\PythonSoftwareFoundation.Python.3.11_qbz5n2kfra8p0\LocalCache\local-packages\Python311\site-packages\aiohttp\web_request.py", line 195, in __init__
    assert transport is not None
           ^^^^^^^^^^^^^^^^^^^^^
AssertionError
ERROR:asyncio:Task exception was never retrieved
future: <Task finished name='Task-104' coro=<RequestHandler.start() done, defined at C:\Users\don00\AppData\Local\Packages\PythonSoftwareFoundation.Python.3.11_qbz5n2kfra8p0\LocalCache\local-packages\Python311\site-packages\aiohttp\web_protocol.py:481> exception=AssertionError()>
Traceback (most recent call last):
  File "C:\Users\don00\AppData\Local\Packages\PythonSoftwareFoundation.Python.3.11_qbz5n2kfra8p0\LocalCache\local-packages\Python311\site-packages\aiohttp\web_protocol.py", line 524, in start
    request = self._request_factory(message, payload, self, writer, handler)
              ^^^^^^^^^^^^^^^^^^^^^^^^^^^^^^^^^^^^^^^^^^^^^^^^^^^^^^^^^^^^^^
  File "C:\Users\don00\AppData\Local\Packages\PythonSoftwareFoundation.Python.3.11_qbz5n2kfra8p0\LocalCache\local-packages\Python311\site-packages\aiohttp\web_app.py", line 485, in _make_request
    return _cls(
           ^^^^^
  File "C:\Users\don00\AppData\Local\Packages\PythonSoftwareFoundation.Python.3.11_qbz5n2kfra8p0\LocalCache\local-packages\Python311\site-packages\aiohttp\web_request.py", line 825, in __init__
    super().__init__(*args, **kwargs)
  File "C:\Users\don00\AppData\Local\Packages\PythonSoftwareFoundation.Python.3.11_qbz5n2kfra8p0\LocalCache\local-packages\Python311\site-packages\aiohttp\web_request.py", line 195, in __init__
    assert transport is not None
           ^^^^^^^^^^^^^^^^^^^^^
AssertionError
ERROR:asyncio:Task exception was never retrieved
future: <Task finished name='Task-107' coro=<RequestHandler.start() done, defined at C:\Users\don00\AppData\Local\Packages\PythonSoftwareFoundation.Python.3.11_qbz5n2kfra8p0\LocalCache\local-packages\Python311\site-packages\aiohttp\web_protocol.py:481> exception=AssertionError()>
Traceback (most recent call last):
  File "C:\Users\don00\AppData\Local\Packages\PythonSoftwareFoundation.Python.3.11_qbz5n2kfra8p0\LocalCache\local-packages\Python311\site-packages\aiohttp\web_protocol.py", line 524, in start
    request = self._request_factory(message, payload, self, writer, handler)
              ^^^^^^^^^^^^^^^^^^^^^^^^^^^^^^^^^^^^^^^^^^^^^^^^^^^^^^^^^^^^^^
  File "C:\Users\don00\AppData\Local\Packages\PythonSoftwareFoundation.Python.3.11_qbz5n2kfra8p0\LocalCache\local-packages\Python311\site-packages\aiohttp\web_app.py", line 485, in _make_request
    return _cls(
           ^^^^^
  File "C:\Users\don00\AppData\Local\Packages\PythonSoftwareFoundation.Python.3.11_qbz5n2kfra8p0\LocalCache\local-packages\Python311\site-packages\aiohttp\web_request.py", line 825, in __init__
    super().__init__(*args, **kwargs)
  File "C:\Users\don00\AppData\Local\Packages\PythonSoftwareFoundation.Python.3.11_qbz5n2kfra8p0\LocalCache\local-packages\Python311\site-packages\aiohttp\web_request.py", line 195, in __init__
    assert transport is not None
           ^^^^^^^^^^^^^^^^^^^^^
AssertionError
gc collect
got prompt
